<?xml version="1.0" ?>
<!-- =================================================================================== -->
<!-- |    This document was autogenerated by xacro from hello_leg.urdf.xacro           | -->
<!-- |    EDITING THIS FILE BY HAND IS NOT RECOMMENDED                                 | -->
<!-- =================================================================================== -->
<robot name="hello_leg">
  <!-- Define materials -->
  <material name="darkgray">
    <color rgba="0.1 0.1 0.1 1.0"/>
  </material>
  <material name="silver">
    <color rgba="0.3 0.3 0.3 1.0"/>
  </material>
  <material name="red">
    <color rgba="1 0 0 1"/>
  </material>
  <material name="blue">
    <color rgba="0 0 1 1"/>
  </material>
  <material name="green">
    <color rgba="0 1 0 1"/>
  </material>
  <!-- World -->
  <link name="world"/>
  <joint name="world_to_base_link" type="fixed">
    <parent link="world"/>
    <child link="base_link"/>
    <origin rpy="0 0 0" xyz="0 0 0"/>
  </joint>
  <!-- Base -->
  <link name="base_link">
    <visual>
      <origin rpy="0 0 0" xyz="0 0 0.5"/>
      <geometry>
        <box size="0.07 0.07 1.0"/>
      </geometry>
      <material name="darkgray"/>
    </visual>
    <collision>
      <origin rpy="0 0 0" xyz="0 0 0.5"/>
      <geometry>
        <box size="0.07 0.07 1.0"/>
      </geometry>
    </collision>
    <inertial>
      <mass value="245.00000000000003"/>
      <inertia ixx="20.516708333333334" ixy="0.0" ixz="0.0" iyy="20.516708333333334" iyz="0.0" izz="0.20008333333333336"/>
    </inertial>
  </link>
  <joint name="base_to_hip_joint" type="revolute">
    <parent link="base_link"/>
    <child link="hip_link"/>
    <origin xyz="-0.035 0 0.5"/>
    <limit effort="50" lower="-1.570796326795" upper="1.570796326795" velocity="100"/>
    <axis xyz="1 0 0"/>
  </joint>
  <!-- Hip -->
  <link name="hip_link">
    <visual>
      <origin rpy="0 0 0" xyz="-0.0995 0 0"/>
      <geometry>
        <box size="0.199 0.045 0.045"/>
      </geometry>
      <material name="red"/>
    </visual>
    <collision>
      <origin rpy="0 0 0" xyz="-0.0995 0 0"/>
      <geometry>
        <box size="0.199 0.045 0.045"/>
      </geometry>
    </collision>
    <inertial>
      <mass value="20.14875"/>
      <inertia ixx="0.006800203124999999" ixy="0.0" ixz="0.0" iyy="0.06989265562500001" iyz="0.0" izz="0.06989265562500001"/>
    </inertial>
  </link>
  <joint name="hip_to_upper_joint" type="revolute">
    <parent link="hip_link"/>
    <child link="upper_link"/>
    <origin xyz="-0.199 0 0"/>
    <limit effort="50" lower="-1.570796326795" upper="1.570796326795" velocity="100"/>
    <axis xyz="0 1 0"/>
  </joint>
  <!-- Upper -->
  <link name="upper_link">
    <visual>
      <origin rpy="0 0 0" xyz="0 0 -0.099"/>
      <geometry>
        <box size="0.044 0.044 0.198"/>
      </geometry>
      <material name="blue"/>
    </visual>
    <collision>
      <origin rpy="0 0 0" xyz="0 0 -0.099"/>
      <geometry>
        <box size="0.044 0.044 0.198"/>
      </geometry>
    </collision>
    <inertial>
      <mass value="19.1664"/>
      <inertia ixx="0.06570880800000001" ixy="0.0" ixz="0.0" iyy="0.06570880800000001" iyz="0.0" izz="0.006184358399999999"/>
    </inertial>
  </link>
  <joint name="upper_to_lower_joint" type="revolute">
    <parent link="upper_link"/>
    <child link="lower_link"/>
    <origin xyz="0 0 -0.198"/>
    <limit effort="50" lower="-1.570796326795" upper="1.570796326795" velocity="100"/>
    <axis xyz="0 1 0"/>
  </joint>
  <!-- Lower -->
  <link name="lower_link">
    <visual>
      <origin rpy="0 0 0" xyz="0 0 -0.0915"/>
      <geometry>
        <box size="0.028 0.028 0.183"/>
      </geometry>
      <material name="green"/>
    </visual>
    <collision>
      <origin rpy="0 0 0" xyz="0 0 -0.0915"/>
      <geometry>
        <box size="0.028 0.028 0.183"/>
      </geometry>
    </collision>
    <inertial>
      <mass value="7.1736"/>
      <inertia ixx="0.0204883994" ixy="0.0" ixz="0.0" iyy="0.0204883994" iyz="0.0" izz="0.0009373504000000001"/>
    </inertial>
  </link>
  <joint name="lower_to_tip_link" type="fixed">
    <parent link="lower_link"/>
    <child link="tip_link"/>
    <origin rpy="0 0 0" xyz="0 0 -0.183"/>
  </joint>
  <!-- Tip -->
  <link name="tip_link">
    <visual>
      <origin rpy="0 0 0" xyz="0 0 0"/>
      <geometry>
        <sphere radius="0.02"/>
      </geometry>
      <material name="red"/>
    </visual>
    <collision>
      <origin rpy="0 0 0" xyz="0 0 0"/>
      <geometry>
        <sphere radius="0.02"/>
      </geometry>
    </collision>
    <inertial>
      <mass value="1.675516081914667"/>
      <inertia ixx="0.0002680825731063468" ixy="0.0" ixz="0.0" iyy="0.0002680825731063468" iyz="0.0" izz="0.0002680825731063468"/>
    </inertial>
  </link>
  <!-- ros_control plugin -->
  <gazebo>
    <plugin filename="libgazebo_ros_control.so" name="gazebo_ros_control">
      <robotNamespace>/hello_leg</robotNamespace>
      <robotSimType>gazebo_ros_control/DefaultRobotHWSim</robotSimType>
    </plugin>
  </gazebo>
  <!-- Base -->
  <gazebo reference="base_link">
    <material>Gazebo/Black</material>
  </gazebo>
  <!-- Hip -->
  <gazebo reference="hip_link">
    <material>Gazebo/Red</material>
  </gazebo>
  <!-- Upper -->
  <gazebo reference="upper_link">
    <material>Gazebo/Blue</material>
  </gazebo>
  <!-- Lower -->
  <gazebo reference="lower_link">
    <material>Gazebo/Green</material>
  </gazebo>
  <!-- Transmission -->
  <transmission name="base_to_hip_transmission">
    <type>transmission_interface/SimpleTransmission</type>
    <joint name="base_to_hip_joint">
      <hardwareInterface>hardware_interface/EffortJointInterface</hardwareInterface>
    </joint>
    <actuator name="base_to_hip_motor">
      <hardwareInterface>hardware_interface/EffortJointInterface</hardwareInterface>
      <mechanicalReduction>1</mechanicalReduction>
    </actuator>
  </transmission>
  <transmission name="hip_to_upper_transmission">
    <type>transmission_interface/SimpleTransmission</type>
    <joint name="hip_to_upper_joint">
      <hardwareInterface>hardware_interface/EffortJointInterface</hardwareInterface>
    </joint>
    <actuator name="hip_to_upper_motor">
      <hardwareInterface>hardware_interface/EffortJointInterface</hardwareInterface>
      <mechanicalReduction>1</mechanicalReduction>
    </actuator>
  </transmission>
  <transmission name="upper_to_lower_transmission">
    <type>transmission_interface/SimpleTransmission</type>
    <joint name="upper_to_lower_joint">
      <hardwareInterface>hardware_interface/EffortJointInterface</hardwareInterface>
    </joint>
    <actuator name="upper_to_lower_motor">
      <hardwareInterface>hardware_interface/EffortJointInterface</hardwareInterface>
      <mechanicalReduction>1</mechanicalReduction>
    </actuator>
  </transmission>
</robot>

